<?xml version="1.0" encoding="utf-8"?>
<robot name="xarm6">
  <link name="link_base">
    <inertial>
      <origin rpy="0 0 0" xyz="0 0 0.05"/>
      <mass value="4.0"/>
      <inertia ixx="0.4" ixy="0" ixz="0" iyy="0.4" iyz="0" izz="0.4"/>
    </inertial>
    <visual>
      <geometry>
        <mesh filename="meshes/base.stl"/>
      </geometry>
      <origin rpy="0 0 0" xyz="0 0 0"/>
    </visual>
    <collision>
      <geometry>
        <mesh filename="meshes/base.stl"/>
      </geometry>
      <origin rpy="0 0 0" xyz="0 0 0"/>
    </collision>
  </link>
  
  <link name="link1">
    <inertial>
      <origin rpy="0.36315 -0.01882 0.05206" xyz="-0.002 0.02692 -0.01332"/>
      <mass value="2.16"/>
      <inertia ixx="0.00539487" ixy="0" ixz="0" iyy="0.00519906" iyz="0" izz="0.00281397"/>
    </inertial>
    <visual>
      <geometry>
        <mesh filename="meshes/link1.stl"/>
      </geometry>
      <origin rpy="0 0 0" xyz="0 0 0"/>
    </visual>
    <collision>
      <geometry>
        <mesh filename="meshes/link1.stl"/>
      </geometry>
      <origin rpy="0 0 0" xyz="0 0 0"/>
    </collision>
  </link>
  
  <joint name="joint1" type="revolute">
    <origin rpy="0 0 0" xyz="0 0 0.267"/>
    <parent link="link_base"/>
    <child link="link1"/>
    <axis xyz="0 0 1"/>
    <limit effort="50" lower="-6.28319" upper="6.28319" velocity="3.14"/>
    <dynamics damping="1" friction="1"/>
  </joint>
  
  <link name="link2">
    <inertial>
      <origin rpy="1.31585 0.62062 -0.33897" xyz="0.03531 -0.21398 0.03386"/>
      <mass value="1.71"/>
      <inertia ixx="0.017867" ixy="0" ixz="0" iyy="0.017867" iyz="0" izz="0.017867"/>
    </inertial>
    <visual>
      <geometry>
        <mesh filename="meshes/link2.stl"/>
      </geometry>
      <origin rpy="0 0 0" xyz="0 0 0"/>
    </visual>
    <collision>
      <geometry>
        <mesh filename="meshes/link2.stl"/>
      </geometry>
      <origin rpy="0 0 0" xyz="0 0 0"/>
    </collision>
  </link>
  
  <joint name="joint2" type="revolute">
    <origin rpy="-1.5708 0 0" xyz="0 0 0"/>
    <parent link="link1"/>
    <child link="link2"/>
    <axis xyz="0 0 1"/>
    <limit effort="50" lower="-2.059" upper="2.0944" velocity="3.14"/>
    <dynamics damping="1" friction="1"/>
  </joint>
  
  <link name="link3">
    <inertial>
      <origin rpy="1.5708 0 0" xyz="0.06781 0.10749 0.01457"/>
      <mass value="1.384"/>
      <inertia ixx="0.004543" ixy="0" ixz="0" iyy="0.004543" iyz="0" izz="0.004543"/>
    </inertial>
    <visual>
      <geometry>
        <mesh filename="meshes/link3.stl"/>
      </geometry>
      <origin rpy="0 0 0" xyz="0 0 0"/>
    </visual>
    <collision>
      <geometry>
        <mesh filename="meshes/link3.stl"/>
      </geometry>
      <origin rpy="0 0 0" xyz="0 0 0"/>
    </collision>
  </link>
  
  <joint name="joint3" type="revolute">
    <origin xyz="0.0535 -0.2845 0"/>
    <parent link="link2"/>
    <child link="link3"/>
    <axis xyz="0 0 1"/>
    <limit effort="50" lower="-3.927" upper="0.19198" velocity="3.14"/>
    <dynamics damping="1" friction="1"/>
  </joint>
  
  <link name="link4">
    <inertial>
      <origin rpy="0.14913 -0.02552 0.15638" xyz="-0.00021 0.02578 -0.02538"/>
      <mass value="1.115"/>
      <inertia ixx="0.00440091" ixy="0" ixz="0" iyy="0.00406855" iyz="0" izz="0.00103407"/>
    </inertial>
    <visual>
      <geometry>
        <mesh filename="meshes/link4.stl"/>
      </geometry>
      <origin rpy="0 0 0" xyz="0 0 0"/>
    </visual>
    <collision>
      <geometry>
        <mesh filename="meshes/link4.stl"/>
      </geometry>
      <origin rpy="0 0 0" xyz="0 0 0"/>
    </collision>
  </link>
  
  <joint name="joint4" type="revolute">
    <origin rpy="-1.5708 0 0" xyz="0.0775 0.3425 0"/>
    <parent link="link3"/>
    <child link="link4"/>
    <axis xyz="0 0 1"/>
    <limit effort="50" lower="-6.28319" upper="6.28319" velocity="3.14"/>
    <dynamics damping="1" friction="1"/>
  </joint>
  
  <link name="link5">
    <inertial>
      <origin rpy="-1.21559 -1.00598 -2.21117" xyz="0.05428 0.01781 0.00543"/>
      <mass value="1.275"/>
      <inertia ixx="0.00289757" ixy="0" ixz="0" iyy="0.0023276" iyz="0" izz="0.000951789"/>
    </inertial>
    <visual>
      <geometry>
        <mesh filename="meshes/link5.stl"/>
      </geometry>
      <origin rpy="0 0 0" xyz="0 0 0"/>
    </visual>
    <collision>
      <geometry>
        <mesh filename="meshes/link5.stl"/>
      </geometry>
      <origin rpy="0 0 0" xyz="0 0 0"/>
    </collision>
  </link>
  
  <joint name="joint5" type="revolute">
    <origin rpy="1.5708 0 0" xyz="0 0 0"/>
    <parent link="link4"/>
    <child link="link5"/>
    <axis xyz="0 0 1"/>
    <limit effort="50" lower="-1.69297" upper="3.14159" velocity="3.14"/>
    <dynamics damping="1" friction="1"/>
  </joint>
  
  <link name="link6">
    <inertial>
      <origin rpy="-3.14159 -1.57079 0.0" xyz="0 0.00064 -0.00952"/>
      <mass value="0.1096"/>
      <inertia ixx="7.9715e-05" ixy="0" ixz="0" iyy="4.8111e-05" iyz="0" izz="4.5293e-05"/>
    </inertial>
    <visual>
      <geometry>
        <mesh filename="meshes/link6.stl"/>
      </geometry>
      <origin rpy="0 0 0" xyz="0 0 0"/>
    </visual>
    <collision>
      <geometry>
        <mesh filename="meshes/link6.stl"/>
      </geometry>
      <origin rpy="0 0 0" xyz="0 0 0"/>
    </collision>
  </link>
  
  <joint name="joint6" type="revolute">
    <origin rpy="-1.5708 0 0" xyz="0.076 0.097 0"/>
    <parent link="link5"/>
    <child link="link6"/>
    <axis xyz="0 0 1"/>
    <limit effort="20" lower="-6.28319" upper="6.28319" velocity="3.14"/>
    <dynamics damping="1" friction="1"/>
  </joint>
  
  <link name="link_eef"/>
  
  <joint name="joint_eef" type="fixed">
    <origin rpy="0 0 0" xyz="0 0 0"/>
    <parent link="link6"/>
    <child link="link_eef"/>
  </joint>
</robot>